---
title: "'Catch'는 'Try' 문 내에서 'Finally' 뒤에 사용할 수 없습니다."
ms.date: 07/20/2015
f1_keywords:
- vbc30379
- bc30379
helpviewer_keywords:
- BC30379
ms.assetid: 33d1278b-cf10-4c66-aaf8-08a4372f370b
ms.openlocfilehash: 04df7e345120b9373e5d0f4e3205e8b04e3bd000
ms.sourcegitcommit: 6b308cf6d627d78ee36dbbae8972a310ac7fd6c8
ms.translationtype: MT
ms.contentlocale: ko-KR
ms.lasthandoff: 01/23/2019
ms.locfileid: "54669252"
---
# <a name="catch-cannot-appear-after-finally-within-a-try-statement"></a>'Catch'는 'Try' 문 내에서 'Finally' 뒤에 사용할 수 없습니다.
`Catch` 문이 코드에서 `Finally` 문 블록을 끝내는 `Try` 뒤에 나타납니다. `Catch` 는 `Try...Catch...Finally` 문 블록 내에서 사용해야 합니다.  
  
 **오류 ID:** BC30379  
  
## <a name="to-correct-this-error"></a>이 오류를 해결하려면  
  
1.  `Catch` 문을 코드의 더 적절한 위치로 이동합니다.  
  
## <a name="see-also"></a>참고자료
- [Try...Catch...Finally 문](../../visual-basic/language-reference/statements/try-catch-finally-statement.md)

